Workbook

Sheet LAND generalities
F6: Portfolio Diversity
D8: Offices (Workplaces) | E8: Major Retail Destinations | F8: Leisure and Retail Parks | G8: Mixed-use | H8: Urban Neighbourhoods (Forthcoming)
D9: Victoria, London (HQ) | E9: Bluewater, Kent | F9: Cambridge Leisure Park, Cambridge | G9: MediaCity, Salford | H9: Mayfield, Manchester
D10: West End & Southwark, London | E10: Liverpoool ONE, Liverpool | F10: Cardigan Fields, Leeds | G10: The Zig Zag Building, London | H10: Lewisham Shopping Centre, London
D11: Myo Victoria Street, London | E11: Trinity Leeds, Leeds | F11: Castle Quarter, Oxford
D12: Myo Liverpool Street, London | E12: St. David's, Cardiff | F12: Fountain Park, Edinburgh
D13: Myo St Paul's, London | E13: Gunwharf Quays, Portsmouth | F13: East Kent, Leisure Park
D14: Myo Bankside, London | E14: Westgate, Oxford | F14: Brighton Marina, Brighton
D15: Myo Piccadilly, London | E15: Buchanan Galleries, Glasgow | F15: Bentley Bridge Leisure Park, Wolverhampton
D16: Myo King's Cross, London | F16: Eureka Leisure Park, Ashford
D17: Myo New Street Square, London | F17: Kingsmead Centre, Bath
F18: Ravenside Retail Park, Chesterfield
F19: Regional Retail & Leisure Portfolio (40 more properties)
D27: Offices (Workplaces) | E27: Major Retail Destinations | F27: Leisure and Retail Parks | G27: Mixed-use | H27: Urban Neighbourhoods (Forthcoming) | K27: London (UK) | L27: Elsewhere (UK)
D28: =90-E28-F28-G28-H28 -> 29 | E28: 7 | F28: 50 | G28: 2 | H28: 2 | K28: =_xlfn.CEILING.MATH(90*0.33) -> 30 | L28: =90-K28 -> 60

Sheet LAND Income Statement
B3: Income Statement
E5: Actual | H5: Forecast
E6: 0 | F6: 1 | G6: 2 | H6: 3 | I6: 4 | J6: 5 | L6: Growth | M6: rates | N6: Assumptions
B7: (£M) | C7: 2023 | D7: 2024 | E7: 2025 | F7: 2026 | G7: 2027 | H7: 2028 | I7: 2029 | J7: 2030 | L7: 2026-2027 | M7: 2028-2030 | N7: =L7 -> 2026-2027 | O7: =M7 -> 2028-2030
B8: Rental income | C8: 657 | D8: 652 | E8: 635 | F8: =E8*(1+$L$8) -> 663.575 | G8: =F8*(1+$L$8) -> 693.43587 | H8: =G8*(1+M8) -> 710.77177 | I8: =H8*(1+M8) -> 728.54107 | J8: =I8*(1+M8) -> 746.75459 | L8: 0.045 | M8: 0.025 | N8: Capturing reversionary rental uplifts | O8: Stabilized long-term mkt growth
B9: Finance lease interest | C9: 2 | D9: 1 | E9: 1 | F9: 1 | G9: 1 | H9: 1 | I9: 1 | J9: 1 | L9: 0 | M9: =L9 -> 0 | N9: Fixed contractual income profile | O9: Fixed contractual income profile
B10: Gross rental income (before rents payable) | C10: =C8+C9 -> 659 | D10: =D8+D9 -> 653 | E10: =SUM(E8:E9) -> 636 | F10: =SUM(F8:F9) -> 664.575 | G10: =SUM(G8:G9) -> 694.43587 | H10: =SUM(H8:H9) -> 711.77177 | I10: =SUM(I8:I9) -> 729.54107 | J10: =SUM(J8:J9) -> 747.75459 | L10: =(G10-F10)/F10 -> 0.044932288 | M10: =(J10-H10)/H10 -> 0.050553875 | N10: % variation | O10: % variation
B11: Rents payable | C11: -12 | D11: -12 | E11: -12 | F11: -12 | G11: -12 | H11: -12 | I11: -12 | J11: -12 | L11: =L9 -> 0 | M11: =M9 -> 0 | N11: Fixed long-term lease obligations | O11: Fixed long-term lease obligations
B12: Gross rental income (after rents payable) | C12: =SUM(C10:C11) -> 647 | D12: =D10+D11 -> 641 | E12: =SUM(E10:E11) -> 624 | F12: =SUM(F10:F11) -> 652.575 | G12: =SUM(G10:G11) -> 682.43587 | H12: =SUM(H10:H11) -> 699.77177 | I12: =SUM(I10:I11) -> 717.54107 | J12: =SUM(J10:J11) -> 735.75459 | L12: =(G12-F12)/F12 -> 0.045758534 | M12: =(J12-H12)/H12 -> 0.051420795 | N12: % variation | O12: % variation
B13: Net service charge expense | C13: =SUM(C14:C15) -> -12 | D13: -16 | E13: =SUM(E14:E15) -> -11 | F13: =E13*(1+$L$13) -> -11.22 | G13: =F13*(1+$L$13) -> -11.4444 | H13: =G13*(1+$L$13) -> -11.673288 | I13: =H13*(1+$L$13) -> -11.906754 | J13: =I13*(1+$L$13) -> -12.144889 | L13: 0.02 | M13: =L13 -> 0.02 | N13: Aligned with projected CPI inflation | O13: Aligned with projected CPI inflation
B14: Service charge income | C14: 98 | D14: 123 | E14: 165 | F14: =E14*(1+$L$13) -> 168.3 | G14: =F14*(1+$L$13) -> 171.666 | H14: =G14*(1+$L$13) -> 175.09932 | I14: =H14*(1+$L$13) -> 178.60131 | J14: =I14*(1+$L$13) -> 182.17333 | L14: =L13 -> 0.02 | M14: =M13 -> 0.02
B15: Service charge expense | C15: -110 | D15: -139 | E15: -176 | F15: =E15*(1+$L$13) -> -179.52 | G15: =F15*(1+$L$13) -> -183.1104 | H15: =G15*(1+$L$13) -> -186.77261 | I15: =H15*(1+$L$13) -> -190.50806 | J15: =I15*(1+$L$13) -> -194.31822 | L15: =L14 -> 0.02 | M15: =M14 -> 0.02
B16: Other property related income | C16: 31 | D16: 38 | E16: 46 | F16: =E16*(1+$L$16) -> 47.15 | G16: =F16*(1+$L$16) -> 48.32875 | H16: =G16*(1+$L$16) -> 49.536969 | I16: =H16*(1+$L$16) -> 50.775393 | J16: =I16*(1+$L$16) -> 52.044778 | L16: 0.025 | M16: =L16 -> 0.025 | N16: Active management of secondary income streams | O16: Active management of secondary income streams
B17: Direct property expenditure | C17: -108 | D17: -119 | E17: -118 | F17: =E17*(1+$L$17) -> -121.54 | G17: =F17*(1+$L$17) -> -125.1862 | H17: =G17*(1+$M$17) -> -128.31585 | I17: =H17*(1+$M$17) -> -131.52375 | J17: =I17*(1+$M$17) -> -134.81185 | L17: 0.03 | M17: 0.025 | N17: Initial maintenance and upgrade costs | O17: Stabilization of portfolio maintenance
B18: Movement in bad and doubtful debt provision | C18: 3 | D18: 6 | E18: 11 | F18: =E18 -> 11 | G18: =F18 -> 11 | H18: =G18 -> 11 | I18: =H18 -> 11 | J18: =I18 -> 11 | L18: 0 | M18: 0 | N18: Stabilized prime tenant credit profile | O18: Stabilized prime tenant credit profile
B19: Segment net rental income | C19: =C18+C17+C16+C13+C12 -> 561 | D19: =SUM(D12:D13,D16:D18) -> 550 | E19: =SUM(E16:E18,E13,E12) -> 552 | F19: =SUM(F16:F18,F12:F13) -> 577.965 | G19: =SUM(G16:G18,G12:G13) -> 605.13402 | H19: =SUM(H16:H18,H12:H13) -> 620.3196 | I19: =SUM(I16:I18,I12:I13) -> 635.88595 | J19: =SUM(J16:J18,J12:J13) -> 651.84264 | L19: =(G19-F19)/F19 -> 0.04700808 | M19: =(J19-H19)/H19 -> 0.050817416 | N19: % variation | O19: % variation
B20: Other income | C20: 3 | D20: 1 | E20: 1 | F20: =E20*(1+$L$20) -> 1.025 | G20: =F20*(1+$L$20) -> 1.050625 | H20: =G20*(1+$L$20) -> 1.0768906 | I20: =H20*(1+$L$20) -> 1.1038129 | J20: =I20*(1+$L$20) -> 1.1314082 | L20: 0.025 | M20: 0.025 | N20: Active management of secondary income streams | O20: Active management of secondary income streams
B21: Administrative expenses | C21: -82 | D21: -74 | E21: -71 | F21: =E21*(1+$L$21) -> -69.58 | G21: =F21*(1+$L$21) -> -68.1884 | H21: =G21*(1+$M$21) -> -69.552168 | I21: =H21*(1+$M$21) -> -70.943211 | J21: =I21*(1+$M$21) -> -72.362076 | L21: -0.02 | M21: 0.02 | N21: Realization of cost-saving efficiencies | O21: Aligned with projected CPI inflation
B22: Depreciation, including amortisation of software | C22: -5 | D22: -4 | E22: -3 | F22: =E22 -> -3 | G22: =F22 -> -3 | H22: =G22 -> -3 | I22: =H22 -> -3 | J22: =I22 -> -3 | L22: 0 | M22: 0 | N22: Fixed asset base maintenance. | O22: Fixed asset base maintenance.
B23: Operating profit before changes in fair value and other adjustments | C23: =SUM(C19:C22) -> 477 | D23: =SUM(D19:D22) -> 473 | E23: =SUM(E19:E22) -> 479 | F23: =SUM(F19:F22) -> 506.41 | G23: =SUM(G19:G22) -> 534.99625 | H23: =SUM(H19:H22) -> 548.84432 | I23: =SUM(I19:I22) -> 563.04656 | J23: =SUM(J19:J22) -> 577.61197 | L23: =(G23-F23)/F23 -> 0.056448826 | M23: =(J23-H23)/H23 -> 0.052414953 | N23: % variation | O23: % variation
B24: Share of post-tax loss from joint ventures | C24: 1 | D24: 0 | E24: 0 | F24: =$E$24 -> 0 | G24: =$E$24 -> 0 | H24: =$E$24 -> 0 | I24: =$E$24 -> 0 | J24: =$E$24 -> 0 | L24: =L22 -> 0 | M24: =M22 -> 0 | N24: Stabilized performance of partnerships | O24: Stabilized performance of partnerships
B25: Loss on disposal of investment properties | C25: -144 | D25: -16 | E25: -12 | F25: =(E25)*(1+$L$25) -> -12.18 | G25: =(F25)*(1+$L$25) -> -12.3627 | H25: =(G25)*(1+$L$25) -> -12.54814 | I25: =(H25)*(1+$L$25) -> -12.736363 | J25: =(I25)*(1+$L$25) -> -12.927408 | L25: 0.015 | M25: =L25 -> 0.015 | N25: Fixed estimated transaction friction and costs. | O25: Fixed estimated transaction friction and costs.
B26: Net surplus (deficit) on revaluation of investment properties | C26: -848 | D26: -625 | E26: 107 | F26: =E26*(1+$L$26) -> 109.14 | G26: =F26*(1+$L$26) -> 111.3228 | H26: =G26*(1+$L$26) -> 113.54926 | I26: =H26*(1+$L$26) -> 115.82024 | J26: =I26*(1+$L$26) -> 118.13665 | L26: 0.02 | M26: =L26 -> 0.02 | N26: Long-term asset value appreciation | O26: Long-term asset value appreciation
B27: Net development contract and transaction expenditure | C27: -9 | D27: -18 | E27: 1 | F27: =E27*(1+$L$27) -> 1.015 | G27: =F27*(1+$L$27) -> 1.030225 | H27: =G27*(1+$L$27) -> 1.0456784 | I27: =H27*(1+$L$27) -> 1.0613636 | J27: =I27*(1+$L$27) -> 1.077284 | L27: =L25 -> 0.015 | M27: =M25 -> 0.015 | N27: Inflationary increase in project spending | O27: Inflationary increase in project spending
B28: Fair value gain on remeasurement of investment | C28: 0 | D28: 3 | E28: 0 | F28: =$E$24 -> 0 | G28: =$E$24 -> 0 | H28: =$E$24 -> 0 | I28: =$E$24 -> 0 | J28: =$E$24 -> 0 | L28: 0 | M28: =L28 -> 0 | N28: Non-recurring accounting valuation adjustment | O28: Non-recurring accounting valuation adjustment
B29: Impairment Reversal (Impairment) of amounts due from joint ventures | C29: 0 | D29: -2 | E29: 1 | F29: =E29 -> 1 | G29: =F29 -> 1 | H29: =G29 -> 1 | I29: =H29 -> 1 | J29: =I29 -> 1 | L29: =M29 -> 0 | M29: 0 | N29: Absence of further asset devaluations | O29: Absence of further asset devaluations
B30: Impairment of goodwill | C30: -5 | D30: -1 | E30: -22 | F30: =E30 -> -22 | G30: =F30 -> -22 | H30: =G30 -> -22 | I30: =H30 -> -22 | J30: =I30 -> -22 | L30: =L28 -> 0 | M30: =M28 -> 0 | N30: No projected intangible asset write-downs | O30: No projected intangible asset write-downs
B31: Impairment of trading properties | C31: -19 | D31: -11 | E31: -4 | F31: =E31*(1+$L$31) -> -4.1 | G31: =F31*(1+$L$31) -> -4.2025 | H31: =G31*(1+$L$31) -> -4.3075625 | I31: =H31*(1+$L$31) -> -4.4152516 | J31: =I31*(1+$L$31) -> -4.5256329 | L31: 0.025 | M31: =L31 -> 0.025 | N31: Conservative buffer for market volatility | O31: Conservative buffer for market volatility
B32: Depreciation | C32: -3 | D32: -2 | E32: -1 | F32: =E32*(1+$L$32) -> -1.02 | G32: =F32*(1+$L$32) -> -1.0404 | H32: =G32*(1+$L$32) -> -1.061208 | I32: =H32*(1+$L$32) -> -1.0824322 | J32: =I32*(1+$L$32) -> -1.1040808 | L32: 0.02 | M32: 0.02 | N32: =N13 -> Aligned with projected CPI inflation | O32: =N32 -> Aligned with projected CPI inflation
B33: Other costs | C33: -6 | D33: -1 | E33: -13 | F33: =E33 -> -13 | G33: =F33 -> -13 | H33: =G33 -> -13 | I33: =H33 -> -13 | J33: =I33 -> -13 | L33: 0 | M33: 0 | N33: Stabilized non-operating cost base | O33: Stabilized non-operating cost base
B34: Operating (loss)/profit | C34: =SUM(C23:C33) -> -556 | D34: =SUM(D23:D33) -> -200 | E34: =SUM(E23:E33) -> 536 | F34: =SUM(F23:F33) -> 565.265 | G34: =SUM(G23:G33) -> 595.74367 | H34: =SUM(H23:H33) -> 611.52234 | I34: =SUM(I23:I33) -> 627.69411 | J34: =SUM(J23:J33) -> 644.26878 | L34: =(G34-F34)/F34 -> 0.053919268 | M34: =(J34-H34)/H34 -> 0.053549039 | N34: % variation | O34: % variation
B35: Finance income | C35: 35 | D35: 12 | E35: 15 | F35: =E35 -> 15 | G35: =F35 -> 15 | H35: =G35 -> 15 | I35: =H35 -> 15 | J35: =I35 -> 15 | L35: 0 | M35: 0 | N35: Conservative flat cash return outlook | O35: Conservative flat cash return outlook
B36: Finance expense | C36: -98 | D36: -131 | E36: -158 | F36: =E36*(1+$L$36) -> -160.37 | G36: =F36*(1+$L$36) -> -162.77555 | H36: =G36*(1+$M$36) -> -165.21718 | I36: =H36*(1+$M$36) -> -167.69544 | J36: =I36*(1+$M$36) -> -170.21087 | L36: 0.015 | M36: =L36 -> 0.015 | N36: Projected marginal borrowing cost increase | O36: Projected marginal borrowing cost increase
B37: (Loss)/profit before tax Taxation | C37: =SUM(C34:C36) -> -619 | D37: =SUM(D34:D36) -> -319 | E37: =E34+E35+E36 -> 393 | F37: =SUM(F34:F36) -> 419.895 | G37: =SUM(G34:G36) -> 447.96812 | H37: =SUM(H34:H36) -> 461.30516 | I37: =SUM(I34:I36) -> 474.99867 | J37: =SUM(J34:J36) -> 489.0579 | L37: =(G37-F37)/F37 -> 0.066857488 | M37: =(J37-H37)/H37 -> 0.060161357 | N37: % variation | O37: % variation
B38: Taxation | C38: 0 | D38: 0 | E38: 3 | F38: =D38 -> 0 | G38: =F38 -> 0 | H38: =F38 -> 0 | I38: =G38 -> 0 | J38: =H38 -> 0 | L38: 0 | M38: =L38 -> 0 | N38: REIT status tax-exempt profile. | O38: REIT status tax-exempt profile.
B39: (Loss)/profit for the year | C39: =C37 -> -619 | D39: =SUM(D37:D38) -> -319 | E39: =E38+E37 -> 396 | F39: =SUM(F37:F38) -> 419.895 | G39: =SUM(G37:G38) -> 447.96812 | H39: =SUM(H37:H38) -> 461.30516 | I39: =SUM(I37:I38) -> 474.99867 | J39: =SUM(J37:J38) -> 489.0579 | L39: =(G39-F39)/F39 -> 0.066857488 | M39: =(J39-H39)/H39 -> 0.060161357 | N39: % variation | O39: % variation
B40: Earnings per share - basic (p) | C40: =C39/C58*100 -> -83.648649 | D40: =D39/D58*100 -> -43.049933 | E40: =E39/E58*100 -> 53.297443 | F40: =F39/$F$58*100 -> 56.361745 | G40: =G39/$F$58*100 -> 60.12995 | H40: =H39/$F$58*100 -> 61.920156 | I40: =I39/$F$58*100 -> 63.758211 | J40: =J39/$F$58*100 -> 65.645356 | L40: =(G40-F40)/F40 -> 0.066857488 | M40: =(J40-H40)/H40 -> 0.060161357 | N40: % variation | O40: % variation
B41: Earnings per share - diluted (p) | C41: =C40 -> -83.648649 | D41: =D39/D58*100 -> -43.049933 | E41: =E39/E59*100 -> 53.012048 | F41: =F39/$F$59*100 -> 56.210843 | G41: =G39/$F$59*100 -> 59.968959 | H41: =H39/$F$59*100 -> 61.754372 | I41: =I39/$F$59*100 -> 63.587506 | J41: =J39/$F$59*100 -> 65.469599 | L41: =(G41-F41)/F41 -> 0.066857488 | M41: =(J41-H41)/H41 -> 0.060161357 | N41: % variation | O41: % variation
B43: EPRA Earnings per share
B44: Total comprehensive income (attributed to shareholders) | C44: =C39 -> -619 | D44: =D39 -> -319 | E44: =E39 -> 396 | F44: =F39 -> 419.895 | G44: =G39 -> 447.96812 | H44: =H39 -> 461.30516 | I44: =I39 -> 474.99867 | J44: =J39 -> 489.0579
...

Sheet LAND Valuation-Multiples
E3: Actual | L3: Forecast
E5: 0 | J5: 1 | K5: 2 | L5: 3 | M5: 4 | N5: 5
E7: 2025 | J7: 2026 | K7: 2027 | L7: 2028 | M7: 2029 | N7: 2030
D9: Landsec | E9: British Land | F9: Derwent London | I9: EPRA EPS (in p) | J9: ='LAND Income Statement'!F61 -> 49.715306 | K9: ='LAND Income Statement'!G61 -> 53.220085 | L9: ='LAND Income Statement'!H61 -> 54.747051 | M9: ='LAND Income Statement'!I61 -> 56.316526 | N9: ='LAND Income Statement'!J61 -> 57.929643
C10: Balance Sheet | D10: (£M) | E10: (£M) | F10: (£M) | I10: Average P/EPRA EPS Ratio | N10: =F27 -> 15.88 x
C11: Assets | D11: 10900 | E11: 8683 | F11: 5094
C12: Net Debt | D12: 4341 | E12: 3614 | F12: 1450
C13: NTA (Net Worth) | D13: 6511 | E13: 5180 | F13: 3615
C14: Income Statement | D14: (£M) | E14: (£M) | F14: (£M) | I14: Terminal Value (in p) | J14: 920 | M14: vvvvvvv Valuation | N14: Inputs
C15: Revenues | D15: ='LAND Income Statement'!E10 -> 636 | E15: 484 | F15: 218 | I15: Discount Factor (Cost of Equity) | J15: =N18 -> 0.10025 | M15: Risk-free rate (Rf) | N15: 0.048
C16: EBITDA | D16: ='LAND Income Statement'!E23-'LAND Income Statement'!E22 -> 482 | E16: 349 | F16: 161 | I16: Landsec Implied Share Price (in p) | J16: =J14/((1+J15)^5) -> 570.59891 | M16: Landsec 𝛽 | N16: 0.95
C17: EPRA Earnings | D17: ='LAND Income Statement'!E57 -> 374 | E17: 279 | F17: 110 | I17: Landsec Implied Equity Value (£M) | J17: =(_xlfn.CEILING.MATH(J16*D20))/100 -> 4262.38 | M17: Makret Risk Premium (Rm-Rf) | N17: 0.055
C18: Market Data | M18: Cost of Equity (Ke) | N18: =N15+N16*N17 -> 0.10025
C19: Share Price (in p) | D19: 551 | E19: 370.4 | F19: 1846
C20: Shares Outsanding (£M) | D20: ='LAND Income Statement'!E59 -> 747 | E20: 999 | F20: 112 | I20: Discount to current Equity Value | J20: =(J17-D22)/J17 -> 0.034349354
C21: EPRA EPS (in p) | D21: ='LAND Income Statement'!E61 -> 50.066934 | E21: 28.5 | F21: 98.4
C22: =C30 -> Market Cap (in £M) | D22: =(D19*D20)/100 -> 4115.97 | E22: =(E20*E19)/100 -> 3700.296 | F22: =(F19*F20)/100 -> 2067.52
C26: Multiples | D26: =E9 -> British Land | E26: =F9 -> Derwent London | F26: Average | G26: Landsec Implied Equity Value (£M)
C27: P/EPRA EPS Ratio | D27: 12,99 x | E27: 18.76 x | F27: 15.88 x | G27: 5939
C28: MV/BV | D28: 0.71 x | E28: 0.57 x | F28: 0.64 x | G28: 4167
C29: EV/EBITDA | D29: 20.95 x | E29: 21.84 x | F29: 21.39 x | G29: 5969
C30: Market Cap (in £M) | D30: =E22 -> 3700.296 | E30: =F22 -> 2067.52 | F30: =AVERAGE(D30:E30) -> 2883.908 | G30: =AVERAGE(G27:G29) -> 5358.3333

Sheet LAND Valuation-DDM
F8: Actual | I8: Forecast
F9: 0 | G9: 1 | H9: 2 | I9: 3 | J9: 4 | K9: 5
D10: 2023 | E10: 2024 | F10: 2025 | G10: 2026 | H10: 2027 | I10: 2028 | J10: 2029 | K10: 2030
C11: Dividend per share (p) | D11: ='LAND Income Statement'!C62 -> 38.6 | E11: ='LAND Income Statement'!D62 -> 39.6 | F11: ='LAND Income Statement'!E62 -> 40.4 | G11: ='LAND Income Statement'!F62 -> 42.218 | H11: ='LAND Income Statement'!G62 -> 44.11781 | I11: ='LAND Income Statement'!H62 -> 45.220755 | J11: ='LAND Income Statement'!I62 -> 46.351274 | K11: ='LAND Income Statement'!J62 -> 47.510056
C12: Dividend Payout Ratio (%) | D12: ='LAND Income Statement'!C63 -> 0.72681934 | E12: ='LAND Income Statement'!D63 -> 0.79093261 | F12: ='LAND Income Statement'!E63 -> 0.80259893 | G12: ='LAND Income Statement'!F63 -> 0.84692161 | H12: ='LAND Income Statement'!G63 -> 0.82674972 | I12: ='LAND Income Statement'!H63 -> 0.82378286 | J12: ='LAND Income Statement'!I63 -> 0.82084563 | K12: ='LAND Income Statement'!J63 -> 0.81793796
C16: Discount factor (Cost of Equity) | G16: ='LAND Valuation-Multiples'!$N$18 -> 0.10025 | H16: ='LAND Valuation-Multiples'!$N$18 -> 0.10025 | I16: ='LAND Valuation-Multiples'!$N$18 -> 0.10025 | J16: ='LAND Valuation-Multiples'!$N$18 -> 0.10025 | K16: ='LAND Valuation-Multiples'!$N$18 -> 0.10025
C17: Perpetual Growth Rate | K17: 0.02
C18: PV of dividends | G18: =(G11)/((1+$G$16)^G9) -> 38.371279 | H18: =(H11)/((1+$G$16)^H9) -> 36.444432 | I18: =(I11)/((1+$G$16)^I9) -> 33.951868 | J18: =(J11)/((1+$G$16)^J9) -> 31.62978 | K18: =(K11)/((1+$G$16)^K9) -> 29.466507
C19: Sum of PV of dividends | D19: =SUM(G18:K18) -> 169.86387
C20: Terminal Value per share (in p) | D20: =(K11*(1+K17))/(G16-K17) -> 603.86613
C21: Fair Value per share (in p) | D21: =D20+D19 -> 773.73
C22: Land Implied Equity Value (£M) | D22: =(D21*'LAND Income Statement'!E59)/100 -> 5779.7631
C24: Discount to current Equity Value | D24: =(D22-'LAND Valuation-Multiples'!D22)/'LAND Valuation-DDM'!D22 -> 0.28786528

Sheet LAND Final Valuation
D10: Valuation Summary | I10: Estimation (in p) | J10: Weight Assigned
D12: Implied Share Price- Earnings Multiple Approach | I12: ='LAND Valuation-Multiples'!J16 -> 570.59891 | J12: 0.5
D13: Implied Share Price- DDM | I13: ='LAND Valuation-DDM'!D21 -> 773.73 | J13: =J12 -> 0.5
D14: Final Valuation Result | I14: =((I12*J12)+(I13*J13))/(J12+J13) -> 672.16446 | J14: =J13+J12 -> 1
D16: Current Market Share Price (2025) | I16: ='LAND Valuation-Multiples'!D19 -> 551
D17: Discount to estimated fair value | I17: =(I14-I16)/I14 -> 0.18026014
